<?xml version="1.0"?>
<robot name="alohamini">

  <!-- Materials -->
  <material name="grey">
    <color rgba="0.5 0.5 0.5 1.0"/>
  </material>
  <material name="black">
    <color rgba="0.1 0.1 0.1 1.0"/>
  </material>
  <material name="white">
    <color rgba="1.0 1.0 1.0 1.0"/>
  </material>
  <material name="orange">
    <color rgba="1.0 0.5 0.0 1.0"/>
  </material>

  <!-- Base Link (Chassis Center) -->
  <link name="base_link">
    <visual>
      <geometry>
        <cylinder length="0.05" radius="0.15"/>
      </geometry>
      <origin xyz="0 0 0.05" rpy="0 0 0"/>
      <material name="grey"/>
    </visual>
    <collision>
      <geometry>
        <cylinder length="0.05" radius="0.15"/>
      </geometry>
      <origin xyz="0 0 0.05" rpy="0 0 0"/>
    </collision>
  </link>

  <!-- Omni Wheels (Visual only for now) -->
  <link name="left_wheel">
    <visual>
      <geometry>
        <cylinder length="0.02" radius="0.05"/>
      </geometry>
      <origin xyz="0 0 0" rpy="1.5708 0 0"/>
      <material name="black"/>
    </visual>
  </link>
  <joint name="base_left_wheel" type="continuous">
    <parent link="base_link"/>
    <child link="left_wheel"/>
    <origin xyz="-0.1 0.1 0.05" rpy="0 0 2.0944"/> <!-- 120 deg -->
    <axis xyz="0 1 0"/>
  </joint>

  <link name="right_wheel">
    <visual>
      <geometry>
        <cylinder length="0.02" radius="0.05"/>
      </geometry>
      <origin xyz="0 0 0" rpy="1.5708 0 0"/>
      <material name="black"/>
    </visual>
  </link>
  <joint name="base_right_wheel" type="continuous">
    <parent link="base_link"/>
    <child link="right_wheel"/>
    <origin xyz="0.1 0.1 0.05" rpy="0 0 -2.0944"/> <!-- -120 deg -->
    <axis xyz="0 1 0"/>
  </joint>

  <link name="back_wheel">
    <visual>
      <geometry>
        <cylinder length="0.02" radius="0.05"/>
      </geometry>
      <origin xyz="0 0 0" rpy="1.5708 0 0"/>
      <material name="black"/>
    </visual>
  </link>
  <joint name="base_back_wheel" type="continuous">
    <parent link="base_link"/>
    <child link="back_wheel"/>
    <origin xyz="0 -0.15 0.05" rpy="0 0 0"/>
    <axis xyz="0 1 0"/>
  </joint>


  <!-- Lift Column -->
  <link name="lift_base_link">
     <visual>
      <geometry>
        <box size="0.05 0.05 0.6"/>
      </geometry>
      <origin xyz="0 0 0.3" rpy="0 0 0"/>
      <material name="white"/>
    </visual>
  </link>
  <joint name="lift_base_joint" type="fixed">
    <parent link="base_link"/>
    <child link="lift_base_link"/>
    <origin xyz="-0.1 0 0.1" rpy="0 0 0"/>
  </joint>

  <!-- Lift Moving Platform -->
  <link name="lift_link">
    <visual>
      <geometry>
        <box size="0.2 0.05 0.02"/>
      </geometry>
      <origin xyz="0.05 0 0" rpy="0 0 0"/>
      <material name="orange"/>
    </visual>
  </link>
  <joint name="lift_axis" type="prismatic">
    <parent link="lift_base_link"/>
    <child link="lift_link"/>
    <origin xyz="0 0 0.05" rpy="0 0 0"/>
    <axis xyz="0 0 1"/>
    <limit lower="0.0" upper="0.6" effort="100" velocity="0.5"/>
  </joint>

  <!-- ================= LEFT ARM ================= -->
  
  <joint name="left_arm_mount" type="fixed">
    <parent link="lift_link"/>
    <child link="left_shoulder_link"/>
    <origin xyz="0.1 0.1 0" rpy="0 0 0.785"/> 
  </joint>

  <link name="left_shoulder_link">
    <visual>
      <geometry><box size="0.04 0.04 0.04"/></geometry>
      <material name="grey"/>
    </visual>
  </link>

  <joint name="arm_left_shoulder_pan" type="revolute">
    <parent link="left_shoulder_link"/>
    <child link="left_shoulder_pan_link"/>
    <origin xyz="0 0 0.02" rpy="0 0 0"/>
    <axis xyz="0 0 1"/>
    <limit lower="-3.14" upper="3.14" effort="10" velocity="3.0"/>
  </joint>
  <link name="left_shoulder_pan_link">
    <visual><geometry><cylinder length="0.04" radius="0.02"/></geometry><material name="black"/></visual>
  </link>

  <joint name="arm_left_shoulder_lift" type="revolute">
    <parent link="left_shoulder_pan_link"/>
    <child link="left_upper_arm_link"/>
    <origin xyz="0 0 0.04" rpy="1.57 0 0"/>
    <axis xyz="0 0 1"/>
    <limit lower="-3.14" upper="3.14" effort="10" velocity="3.0"/>
  </joint>
  <link name="left_upper_arm_link">
     <visual>
        <geometry><box size="0.15 0.03 0.03"/></geometry>
        <origin xyz="0.075 0 0" rpy="0 0 0"/>
        <material name="white"/>
     </visual>
  </link>

  <joint name="arm_left_elbow_flex" type="revolute">
    <parent link="left_upper_arm_link"/>
    <child link="left_forearm_link"/>
    <origin xyz="0.15 0 0" rpy="0 0 0"/>
    <axis xyz="0 0 1"/>
    <limit lower="-3.14" upper="3.14" effort="10" velocity="3.0"/>
  </joint>
  <link name="left_forearm_link">
     <visual>
        <geometry><box size="0.15 0.03 0.03"/></geometry>
        <origin xyz="0.075 0 0" rpy="0 0 0"/>
        <material name="white"/>
     </visual>
  </link>

  <joint name="arm_left_wrist_flex" type="revolute">
    <parent link="left_forearm_link"/>
    <child link="left_wrist_flex_link"/>
    <origin xyz="0.15 0 0" rpy="0 0 0"/>
    <axis xyz="0 0 1"/>
    <limit lower="-3.14" upper="3.14" effort="10" velocity="3.0"/>
  </joint>
  <link name="left_wrist_flex_link">
    <visual><geometry><cylinder length="0.04" radius="0.015"/></geometry><material name="black"/></visual>
  </link>

  <joint name="arm_left_wrist_roll" type="revolute">
    <parent link="left_wrist_flex_link"/>
    <child link="left_gripper_base_link"/>
    <origin xyz="0.04 0 0" rpy="1.57 0 0"/>
    <axis xyz="0 0 1"/>
    <limit lower="-3.14" upper="3.14" effort="10" velocity="3.0"/>
  </joint>
  <link name="left_gripper_base_link">
     <visual>
        <geometry><box size="0.05 0.02 0.04"/></geometry>
        <origin xyz="0.025 0 0" rpy="0 0 0"/>
        <material name="grey"/>
     </visual>
  </link>

  <joint name="arm_left_gripper" type="revolute">
    <parent link="left_gripper_base_link"/>
    <child link="left_gripper_finger"/>
    <origin xyz="0.05 0 0" rpy="0 0 0"/>
    <axis xyz="0 0 1"/>
    <limit lower="-1.0" upper="1.0" effort="5" velocity="5.0"/>
  </joint>
  <link name="left_gripper_finger">
    <visual>
        <geometry><box size="0.04 0.01 0.01"/></geometry>
        <origin xyz="0.02 0 0" rpy="0 0 0"/>
        <material name="black"/>
     </visual>
  </link>


  <!-- ================= RIGHT ARM ================= -->

  <joint name="right_arm_mount" type="fixed">
    <parent link="lift_link"/>
    <child link="right_shoulder_link"/>
    <origin xyz="0.1 -0.1 0" rpy="0 0 -0.785"/> 
  </joint>

  <link name="right_shoulder_link">
    <visual>
      <geometry><box size="0.04 0.04 0.04"/></geometry>
      <material name="grey"/>
    </visual>
  </link>

  <joint name="arm_right_shoulder_pan" type="revolute">
    <parent link="right_shoulder_link"/>
    <child link="right_shoulder_pan_link"/>
    <origin xyz="0 0 0.02" rpy="0 0 0"/>
    <axis xyz="0 0 1"/>
    <limit lower="-3.14" upper="3.14" effort="10" velocity="3.0"/>
  </joint>
  <link name="right_shoulder_pan_link">
    <visual><geometry><cylinder length="0.04" radius="0.02"/></geometry><material name="black"/></visual>
  </link>

  <joint name="arm_right_shoulder_lift" type="revolute">
    <parent link="right_shoulder_pan_link"/>
    <child link="right_upper_arm_link"/>
    <origin xyz="0 0 0.04" rpy="1.57 0 0"/>
    <axis xyz="0 0 1"/>
    <limit lower="-3.14" upper="3.14" effort="10" velocity="3.0"/>
  </joint>
  <link name="right_upper_arm_link">
     <visual>
        <geometry><box size="0.15 0.03 0.03"/></geometry>
        <origin xyz="0.075 0 0" rpy="0 0 0"/>
        <material name="white"/>
     </visual>
  </link>

  <joint name="arm_right_elbow_flex" type="revolute">
    <parent link="right_upper_arm_link"/>
    <child link="right_forearm_link"/>
    <origin xyz="0.15 0 0" rpy="0 0 0"/>
    <axis xyz="0 0 1"/>
    <limit lower="-3.14" upper="3.14" effort="10" velocity="3.0"/>
  </joint>
  <link name="right_forearm_link">
     <visual>
        <geometry><box size="0.15 0.03 0.03"/></geometry>
        <origin xyz="0.075 0 0" rpy="0 0 0"/>
        <material name="white"/>
     </visual>
  </link>

  <joint name="arm_right_wrist_flex" type="revolute">
    <parent link="right_forearm_link"/>
    <child link="right_wrist_flex_link"/>
    <origin xyz="0.15 0 0" rpy="0 0 0"/>
    <axis xyz="0 0 1"/>
    <limit lower="-3.14" upper="3.14" effort="10" velocity="3.0"/>
  </joint>
  <link name="right_wrist_flex_link">
    <visual><geometry><cylinder length="0.04" radius="0.015"/></geometry><material name="black"/></visual>
  </link>

  <joint name="arm_right_wrist_roll" type="revolute">
    <parent link="right_wrist_flex_link"/>
    <child link="right_gripper_base_link"/>
    <origin xyz="0.04 0 0" rpy="1.57 0 0"/>
    <axis xyz="0 0 1"/>
    <limit lower="-3.14" upper="3.14" effort="10" velocity="3.0"/>
  </joint>
  <link name="right_gripper_base_link">
     <visual>
        <geometry><box size="0.05 0.02 0.04"/></geometry>
        <origin xyz="0.025 0 0" rpy="0 0 0"/>
        <material name="grey"/>
     </visual>
  </link>

  <joint name="arm_right_gripper" type="revolute">
    <parent link="right_gripper_base_link"/>
    <child link="right_gripper_finger"/>
    <origin xyz="0.05 0 0" rpy="0 0 0"/>
    <axis xyz="0 0 1"/>
    <limit lower="-1.0" upper="1.0" effort="5" velocity="5.0"/>
  </joint>
  <link name="right_gripper_finger">
    <visual>
        <geometry><box size="0.04 0.01 0.01"/></geometry>
        <origin xyz="0.02 0 0" rpy="0 0 0"/>
        <material name="black"/>
     </visual>
  </link>

</robot>
